Workbook

Sheet Planilha1
A1: Material | B1: Descrição | C1: Linha TF | D1: MRP | E1: Coluna1
A2: 14396993 | B2: =VLOOKUP(A2,Planilha2!B:C,2,0) -> INVERSOR NACFW110070T4OFAYWZ | C2: F13 | D2: =VLOOKUP(A2,Planilha2!B:H,7,0) -> LINHA M3 | E2: 29500 | F2: =IFERROR( IF(ISNUMBER(FIND("CFW110",B2)), VALUE(MID(B2,FIND("CFW110",B2)+6,FIND("T",B2,FIND("CFW110",B2))-(FIND("CFW110",B2)+6))), IF(ISNUMBER(FIND("D",B2)), VALUE(SUBSTITUTE(MID(B2,FIND("D",B2)+1,FIND("T",B2,FIND("D",B2))-(FIND("D",B2)+1)),"P",",")), IF(ISNUMBER(FIND("CFW5",B2)), VALUE(MID(B2, IF(ISNUMBER(FIND("F",B2)),FIND("F",B2)+1,FIND("G",B2)+1), FIND("T",B2)-(IF(ISNUMBER(FIND("F",B2)),FIND("F",B2)+1,FIND("G",B2)+1)) )), VALUE(MID(B2,FIND("E0",B2)+2,FIND("T",B2,FIND("E0",B2))-(FIND("E0",B2)+2))) ))),"") -> 70 | G2: =IFERROR( IF(ISNUMBER(FIND("T2",B2)),220, IF(ISNUMBER(FIND("T4",B2)),440, IF(ISNUMBER(FIND("T5",B2)),575, IF(ISNUMBER(FIND("T6",B2)),690,"")))), "") -> 440
A3: 17224347 | B3: =VLOOKUP(A3,Planilha2!B:C,2,0) -> INVERSOR BRCFW110045T2O55FAYECZ | C3: F13 | D3: =VLOOKUP(A3,Planilha2!B:H,7,0) -> LINHA M3 | E3: 15600 | F3: =IFERROR( IF(ISNUMBER(FIND("CFW110",B3)), VALUE(MID(B3,FIND("CFW110",B3)+6,FIND("T",B3,FIND("CFW110",B3))-(FIND("CFW110",B3)+6))), IF(ISNUMBER(FIND("D",B3)), VALUE(SUBSTITUTE(MID(B3,FIND("D",B3)+1,FIND("T",B3,FIND("D",B3))-(FIND("D",B3)+1)),"P",",")), IF(ISNUMBER(FIND("CFW5",B3)), VALUE(MID(B3, IF(ISNUMBER(FIND("F",B3)),FIND("F",B3)+1,FIND("G",B3)+1), FIND("T",B3)-(IF(ISNUMBER(FIND("F",B3)),FIND("F",B3)+1,FIND("G",B3)+1)) )), VALUE(MID(B3,FIND("E0",B3)+2,FIND("T",B3,FIND("E0",B3))-(FIND("E0",B3)+2))) ))),"") -> 45 | G3: =IFERROR( IF(ISNUMBER(FIND("T2",B3)),220, IF(ISNUMBER(FIND("T4",B3)),440, IF(ISNUMBER(FIND("T5",B3)),575, IF(ISNUMBER(FIND("T6",B3)),690,"")))), "") -> 220
A4: 14676621 | B4: =VLOOKUP(A4,Planilha2!B:C,2,0) -> INVERSOR BRCFW110070T2O55FASSZ | C4: F13 | D4: =VLOOKUP(A4,Planilha2!B:H,7,0) -> LINHA M3 | E4: 0,000 | F4: =IFERROR( IF(ISNUMBER(FIND("CFW110",B4)), VALUE(MID(B4,FIND("CFW110",B4)+6,FIND("T",B4,FIND("CFW110",B4))-(FIND("CFW110",B4)+6))), IF(ISNUMBER(FIND("D",B4)), VALUE(SUBSTITUTE(MID(B4,FIND("D",B4)+1,FIND("T",B4,FIND("D",B4))-(FIND("D",B4)+1)),"P",",")), IF(ISNUMBER(FIND("CFW5",B4)), VALUE(MID(B4, IF(ISNUMBER(FIND("F",B4)),FIND("F",B4)+1,FIND("G",B4)+1), FIND("T",B4)-(IF(ISNUMBER(FIND("F",B4)),FIND("F",B4)+1,FIND("G",B4)+1)) )), VALUE(MID(B4,FIND("E0",B4)+2,FIND("T",B4,FIND("E0",B4))-(FIND("E0",B4)+2))) ))),"") -> 70 | G4: =IFERROR( IF(ISNUMBER(FIND("T2",B4)),220, IF(ISNUMBER(FIND("T4",B4)),440, IF(ISNUMBER(FIND("T5",B4)),575, IF(ISNUMBER(FIND("T6",B4)),690,"")))), "") -> 220
A5: 14677580 | B5: =VLOOKUP(A5,Planilha2!B:C,2,0) -> INVERSOR BRCFW110142T2O55SSZ | C5: F13 | D5: =VLOOKUP(A5,Planilha2!B:H,7,0) -> LINHA E1 | E5: 0,000 | F5: =IFERROR( IF(ISNUMBER(FIND("CFW110",B5)), VALUE(MID(B5,FIND("CFW110",B5)+6,FIND("T",B5,FIND("CFW110",B5))-(FIND("CFW110",B5)+6))), IF(ISNUMBER(FIND("D",B5)), VALUE(SUBSTITUTE(MID(B5,FIND("D",B5)+1,FIND("T",B5,FIND("D",B5))-(FIND("D",B5)+1)),"P",",")), IF(ISNUMBER(FIND("CFW5",B5)), VALUE(MID(B5, IF(ISNUMBER(FIND("F",B5)),FIND("F",B5)+1,FIND("G",B5)+1), FIND("T",B5)-(IF(ISNUMBER(FIND("F",B5)),FIND("F",B5)+1,FIND("G",B5)+1)) )), VALUE(MID(B5,FIND("E0",B5)+2,FIND("T",B5,FIND("E0",B5))-(FIND("E0",B5)+2))) ))),"") -> 142 | G5: =IFERROR( IF(ISNUMBER(FIND("T2",B5)),220, IF(ISNUMBER(FIND("T4",B5)),440, IF(ISNUMBER(FIND("T5",B5)),575, IF(ISNUMBER(FIND("T6",B5)),690,"")))), "") -> 220
A6: 14764545 | B6: =VLOOKUP(A6,Planilha2!B:C,2,0) -> INVERSOR BRCFW110088T4OHALS9Z-UI | C6: F13 | D6: =VLOOKUP(A6,Planilha2!B:H,7,0) -> LINHA M3 | E6: 26175 | F6: =IFERROR( IF(ISNUMBER(FIND("CFW110",B6)), VALUE(MID(B6,FIND("CFW110",B6)+6,FIND("T",B6,FIND("CFW110",B6))-(FIND("CFW110",B6)+6))), IF(ISNUMBER(FIND("D",B6)), VALUE(SUBSTITUTE(MID(B6,FIND("D",B6)+1,FIND("T",B6,FIND("D",B6))-(FIND("D",B6)+1)),"P",",")), IF(ISNUMBER(FIND("CFW5",B6)), VALUE(MID(B6, IF(ISNUMBER(FIND("F",B6)),FIND("F",B6)+1,FIND("G",B6)+1), FIND("T",B6)-(IF(ISNUMBER(FIND("F",B6)),FIND("F",B6)+1,FIND("G",B6)+1)) )), VALUE(MID(B6,FIND("E0",B6)+2,FIND("T",B6,FIND("E0",B6))-(FIND("E0",B6)+2))) ))),"") -> 88 | G6: =IFERROR( IF(ISNUMBER(FIND("T2",B6)),220, IF(ISNUMBER(FIND("T4",B6)),440, IF(ISNUMBER(FIND("T5",B6)),575, IF(ISNUMBER(FIND("T6",B6)),690,"")))), "") -> 440
A7: 14821623 | B7: =VLOOKUP(A7,Planilha2!B:C,2,0) -> INVERSOR BRCFW110088T4OSSZ | C7: F13 | D7: =VLOOKUP(A7,Planilha2!B:H,7,0) -> LINHA M3 | E7: 26000 | F7: =IFERROR( IF(ISNUMBER(FIND("CFW110",B7)), VALUE(MID(B7,FIND("CFW110",B7)+6,FIND("T",B7,FIND("CFW110",B7))-(FIND("CFW110",B7)+6))), IF(ISNUMBER(FIND("D",B7)), VALUE(SUBSTITUTE(MID(B7,FIND("D",B7)+1,FIND("T",B7,FIND("D",B7))-(FIND("D",B7)+1)),"P",",")), IF(ISNUMBER(FIND("CFW5",B7)), VALUE(MID(B7, IF(ISNUMBER(FIND("F",B7)),FIND("F",B7)+1,FIND("G",B7)+1), FIND("T",B7)-(IF(ISNUMBER(FIND("F",B7)),FIND("F",B7)+1,FIND("G",B7)+1)) )), VALUE(MID(B7,FIND("E0",B7)+2,FIND("T",B7,FIND("E0",B7))-(FIND("E0",B7)+2))) ))),"") -> 88 | G7: =IFERROR( IF(ISNUMBER(FIND("T2",B7)),220, IF(ISNUMBER(FIND("T4",B7)),440, IF(ISNUMBER(FIND("T5",B7)),575, IF(ISNUMBER(FIND("T6",B7)),690,"")))), "") -> 440
A8: 11996061 | B8: =VLOOKUP(A8,Planilha2!B:C,2,0) -> INVERSOR NACFW110004T5ON1NFYZ | C8: F13 | D8: =VLOOKUP(A8,Planilha2!B:H,7,0) -> LINHA P7 | E8: 9440 | F8: =IFERROR( IF(ISNUMBER(FIND("CFW110",B8)), VALUE(MID(B8,FIND("CFW110",B8)+6,FIND("T",B8,FIND("CFW110",B8))-(FIND("CFW110",B8)+6))), IF(ISNUMBER(FIND("D",B8)), VALUE(SUBSTITUTE(MID(B8,FIND("D",B8)+1,FIND("T",B8,FIND("D",B8))-(FIND("D",B8)+1)),"P",",")), IF(ISNUMBER(FIND("CFW5",B8)), VALUE(MID(B8, IF(ISNUMBER(FIND("F",B8)),FIND("F",B8)+1,FIND("G",B8)+1), FIND("T",B8)-(IF(ISNUMBER(FIND("F",B8)),FIND("F",B8)+1,FIND("G",B8)+1)) )), VALUE(MID(B8,FIND("E0",B8)+2,FIND("T",B8,FIND("E0",B8))-(FIND("E0",B8)+2))) ))),"") -> 4 | G8: =IFERROR( IF(ISNUMBER(FIND("T2",B8)),220, IF(ISNUMBER(FIND("T4",B8)),440, IF(ISNUMBER(FIND("T5",B8)),575, IF(ISNUMBER(FIND("T6",B8)),690,"")))), "") -> 575
A9: 13226625 | B9: =VLOOKUP(A9,Planilha2!B:C,2,0) -> INVERSOR CFW700C38P0T4DB20C3EC | C9: F13 | D9: =VLOOKUP(A9,Planilha2!B:H,7,0) -> OBSOLETOS DRIVES | E9: 16000 | F9: =IFERROR( IF(ISNUMBER(FIND("CFW110",B9)), VALUE(MID(B9,FIND("CFW110",B9)+6,FIND("T",B9,FIND("CFW110",B9))-(FIND("CFW110",B9)+6))), IF(ISNUMBER(FIND("D",B9)), VALUE(SUBSTITUTE(MID(B9,FIND("D",B9)+1,FIND("T",B9,FIND("D",B9))-(FIND("D",B9)+1)),"P",",")), IF(ISNUMBER(FIND("CFW5",B9)), VALUE(MID(B9, IF(ISNUMBER(FIND("F",B9)),FIND("F",B9)+1,FIND("G",B9)+1), FIND("T",B9)-(IF(ISNUMBER(FIND("F",B9)),FIND("F",B9)+1,FIND("G",B9)+1)) )), VALUE(MID(B9,FIND("E0",B9)+2,FIND("T",B9,FIND("E0",B9))-(FIND("E0",B9)+2))) ))),"") | G9: =IFERROR( IF(ISNUMBER(FIND("T2",B9)),220, IF(ISNUMBER(FIND("T4",B9)),440, IF(ISNUMBER(FIND("T5",B9)),575, IF(ISNUMBER(FIND("T6",B9)),690,"")))), "") -> 440
A10: 13226688 | B10: =VLOOKUP(A10,Planilha2!B:C,2,0) -> INVERSOR CFW700C45P0T4DB20C3Y1EC | C10: F13 | D10: =VLOOKUP(A10,Planilha2!B:H,7,0) -> OBSOLETOS DRIVES | E10: 16000 | F10: =IFERROR( IF(ISNUMBER(FIND("CFW110",B10)), VALUE(MID(B10,FIND("CFW110",B10)+6,FIND("T",B10,FIND("CFW110",B10))-(FIND("CFW110",B10)+6))), IF(ISNUMBER(FIND("D",B10)), VALUE(SUBSTITUTE(MID(B10,FIND("D",B10)+1,FIND("T",B10,FIND("D",B10))-(FIND("D",B10)+1)),"P",",")), IF(ISNUMBER(FIND("CFW5",B10)), VALUE(MID(B10, IF(ISNUMBER(FIND("F",B10)),FIND("F",B10)+1,FIND("G",B10)+1), FIND("T",B10)-(IF(ISNUMBER(FIND("F",B10)),FIND("F",B10)+1,FIND("G",B10)+1)) )), VALUE(MID(B10,FIND("E0",B10)+2,FIND("T",B10,FIND("E0",B10))-(FIND("E0",B10)+2))) ))),"") | G10: =IFERROR( IF(ISNUMBER(FIND("T2",B10)),220, IF(ISNUMBER(FIND("T4",B10)),440, IF(ISNUMBER(FIND("T5",B10)),575, IF(ISNUMBER(FIND("T6",B10)),690,"")))), "") -> 440
A11: 12789099 | B11: =VLOOKUP(A11,Planilha2!B:C,2,0) -> INVERSOR BRCFW110054T2OWZ | C11: F13 | D11: =VLOOKUP(A11,Planilha2!B:H,7,0) -> LINHA M1 | E11: 16000 | F11: =IFERROR( IF(ISNUMBER(FIND("CFW110",B11)), VALUE(MID(B11,FIND("CFW110",B11)+6,FIND("T",B11,FIND("CFW110",B11))-(FIND("CFW110",B11)+6))), IF(ISNUMBER(FIND("D",B11)), VALUE(SUBSTITUTE(MID(B11,FIND("D",B11)+1,FIND("T",B11,FIND("D",B11))-(FIND("D",B11)+1)),"P",",")), IF(ISNUMBER(FIND("CFW5",B11)), VALUE(MID(B11, IF(ISNUMBER(FIND("F",B11)),FIND("F",B11)+1,FIND("G",B11)+1), FIND("T",B11)-(IF(ISNUMBER(FIND("F",B11)),FIND("F",B11)+1,FIND("G",B11)+1)) )), VALUE(MID(B11,FIND("E0",B11)+2,FIND("T",B11,FIND("E0",B11))-(FIND("E0",B11)+2))) ))),"") -> 54 | G11: =IFERROR( IF(ISNUMBER(FIND("T2",B11)),220, IF(ISNUMBER(FIND("T4",B11)),440, IF(ISNUMBER(FIND("T5",B11)),575, IF(ISNUMBER(FIND("T6",B11)),690,"")))), "") -> 220
A12: 12805752 | B12: =VLOOKUP(A12,Planilha2!B:C,2,0) -> INVERSOR CFW701C45P0T2DB20C3H00 | C12: F13 | D12: =VLOOKUP(A12,Planilha2!B:H,7,0) -> OBSOLETOS DRIVES | E12: 16000 | F12: =IFERROR( IF(ISNUMBER(FIND("CFW110",B12)), VALUE(MID(B12,FIND("CFW110",B12)+6,FIND("T",B12,FIND("CFW110",B12))-(FIND("CFW110",B12)+6))), IF(ISNUMBER(FIND("D",B12)), VALUE(SUBSTITUTE(MID(B12,FIND("D",B12)+1,FIND("T",B12,FIND("D",B12))-(FIND("D",B12)+1)),"P",",")), IF(ISNUMBER(FIND("CFW5",B12)), VALUE(MID(B12, IF(ISNUMBER(FIND("F",B12)),FIND("F",B12)+1,FIND("G",B12)+1), FIND("T",B12)-(IF(ISNUMBER(FIND("F",B12)),FIND("F",B12)+1,FIND("G",B12)+1)) )), VALUE(MID(B12,FIND("E0",B12)+2,FIND("T",B12,FIND("E0",B12))-(FIND("E0",B12)+2))) ))),"") | G12: =IFERROR( IF(ISNUMBER(FIND("T2",B12)),220, IF(ISNUMBER(FIND("T4",B12)),440, IF(ISNUMBER(FIND("T5",B12)),575, IF(ISNUMBER(FIND("T6",B12)),690,"")))), "") -> 220
A13: 13253868 | B13: =VLOOKUP(A13,Planilha2!B:C,2,0) -> INVERSOR BRCFW110070T4OFASHZ | C13: F13 | D13: =VLOOKUP(A13,Planilha2!B:H,7,0) -> LINHA M3 | E13: 26260 | F13: =IFERROR( IF(ISNUMBER(FIND("CFW110",B13)), VALUE(MID(B13,FIND("CFW110",B13)+6,FIND("T",B13,FIND("CFW110",B13))-(FIND("CFW110",B13)+6))), IF(ISNUMBER(FIND("D",B13)), VALUE(SUBSTITUTE(MID(B13,FIND("D",B13)+1,FIND("T",B13,FIND("D",B13))-(FIND("D",B13)+1)),"P",",")), IF(ISNUMBER(FIND("CFW5",B13)), VALUE(MID(B13, IF(ISNUMBER(FIND("F",B13)),FIND("F",B13)+1,FIND("G",B13)+1), FIND("T",B13)-(IF(ISNUMBER(FIND("F",B13)),FIND("F",B13)+1,FIND("G",B13)+1)) )), VALUE(MID(B13,FIND("E0",B13)+2,FIND("T",B13,FIND("E0",B13))-(FIND("E0",B13)+2))) ))),"") -> 70 | G13: =IFERROR( IF(ISNUMBER(FIND("T2",B13)),220, IF(ISNUMBER(FIND("T4",B13)),440, IF(ISNUMBER(FIND("T5",B13)),575, IF(ISNUMBER(FIND("T6",B13)),690,"")))), "") -> 440
A14: 13253869 | B14: =VLOOKUP(A14,Planilha2!B:C,2,0) -> INVERSOR BRCFW110088T4OFASHZ | C14: F13 | D14: =VLOOKUP(A14,Planilha2!B:H,7,0) -> LINHA M3 | E14: 26260 | F14: =IFERROR( IF(ISNUMBER(FIND("CFW110",B14)), VALUE(MID(B14,FIND("CFW110",B14)+6,FIND("T",B14,FIND("CFW110",B14))-(FIND("CFW110",B14)+6))), IF(ISNUMBER(FIND("D",B14)), VALUE(SUBSTITUTE(MID(B14,FIND("D",B14)+1,FIND("T",B14,FIND("D",B14))-(FIND("D",B14)+1)),"P",",")), IF(ISNUMBER(FIND("CFW5",B14)), VALUE(MID(B14, IF(ISNUMBER(FIND("F",B14)),FIND("F",B14)+1,FIND("G",B14)+1), FIND("T",B14)-(IF(ISNUMBER(FIND("F",B14)),FIND("F",B14)+1,FIND("G",B14)+1)) )), VALUE(MID(B14,FIND("E0",B14)+2,FIND("T",B14,FIND("E0",B14))-(FIND("E0",B14)+2))) ))),"") -> 88 | G14: =IFERROR( IF(ISNUMBER(FIND("T2",B14)),220, IF(ISNUMBER(FIND("T4",B14)),440, IF(ISNUMBER(FIND("T5",B14)),575, IF(ISNUMBER(FIND("T6",B14)),690,"")))), "") -> 440
A15: 13253827 | B15: =VLOOKUP(A15,Planilha2!B:C,2,0) -> INVERSOR BRCFW110058T4OFASHZ | C15: F13 | D15: =VLOOKUP(A15,Planilha2!B:H,7,0) -> LINHA M1 | E15: 4760 | F15: =IFERROR( IF(ISNUMBER(FIND("CFW110",B15)), VALUE(MID(B15,FIND("CFW110",B15)+6,FIND("T",B15,FIND("CFW110",B15))-(FIND("CFW110",B15)+6))), IF(ISNUMBER(FIND("D",B15)), VALUE(SUBSTITUTE(MID(B15,FIND("D",B15)+1,FIND("T",B15,FIND("D",B15))-(FIND("D",B15)+1)),"P",",")), IF(ISNUMBER(FIND("CFW5",B15)), VALUE(MID(B15, IF(ISNUMBER(FIND("F",B15)),FIND("F",B15)+1,FIND("G",B15)+1), FIND("T",B15)-(IF(ISNUMBER(FIND("F",B15)),FIND("F",B15)+1,FIND("G",B15)+1)) )), VALUE(MID(B15,FIND("E0",B15)+2,FIND("T",B15,FIND("E0",B15))-(FIND("E0",B15)+2))) ))),"") -> 58 | G15: =IFERROR( IF(ISNUMBER(FIND("T2",B15)),220, IF(ISNUMBER(FIND("T4",B15)),440, IF(ISNUMBER(FIND("T5",B15)),575, IF(ISNUMBER(FIND("T6",B15)),690,"")))), "") -> 440
A16: 13253826 | B16: =VLOOKUP(A16,Planilha2!B:C,2,0) -> INVERSOR BRCFW110045T4OFASHZ | C16: F13 | D16: =VLOOKUP(A16,Planilha2!B:H,7,0) -> LINHA M1 | E16: 4760 | F16: =IFERROR( IF(ISNUMBER(FIND("CFW110",B16)), VALUE(MID(B16,FIND("CFW110",B16)+6,FIND("T",B16,FIND("CFW110",B16))-(FIND("CFW110",B16)+6))), IF(ISNUMBER(FIND("D",B16)), VALUE(SUBSTITUTE(MID(B16,FIND("D",B16)+1,FIND("T",B16,FIND("D",B16))-(FIND("D",B16)+1)),"P",",")), IF(ISNUMBER(FIND("CFW5",B16)), VALUE(MID(B16, IF(ISNUMBER(FIND("F",B16)),FIND("F",B16)+1,FIND("G",B16)+1), FIND("T",B16)-(IF(ISNUMBER(FIND("F",B16)),FIND("F",B16)+1,FIND("G",B16)+1)) )), VALUE(MID(B16,FIND("E0",B16)+2,FIND("T",B16,FIND("E0",B16))-(FIND("E0",B16)+2))) ))),"") -> 45 | G16: =IFERROR( IF(ISNUMBER(FIND("T2",B16)),220, IF(ISNUMBER(FIND("T4",B16)),440, IF(ISNUMBER(FIND("T5",B16)),575, IF(ISNUMBER(FIND("T6",B16)),690,"")))), "") -> 440
A17: 13290135 | B17: =VLOOKUP(A17,Planilha2!B:C,2,0) -> INVERSOR CFW700C44P0T5DB20 | C17: F13 | D17: =VLOOKUP(A17,Planilha2!B:H,7,0) -> OBSOLETOS DRIVES | E17: 26000 | F17: =IFERROR( IF(ISNUMBER(FIND("CFW110",B17)), VALUE(MID(B17,FIND("CFW110",B17)+6,FIND("T",B17,FIND("CFW110",B17))-(FIND("CFW110",B17)+6))), IF(ISNUMBER(FIND("D",B17)), VALUE(SUBSTITUTE(MID(B17,FIND("D",B17)+1,FIND("T",B17,FIND("D",B17))-(FIND("D",B17)+1)),"P",",")), IF(ISNUMBER(FIND("CFW5",B17)), VALUE(MID(B17, IF(ISNUMBER(FIND("F",B17)),FIND("F",B17)+1,FIND("G",B17)+1), FIND("T",B17)-(IF(ISNUMBER(FIND("F",B17)),FIND("F",B17)+1,FIND("G",B17)+1)) )), VALUE(MID(B17,FIND("E0",B17)+2,FIND("T",B17,FIND("E0",B17))-(FIND("E0",B17)+2))) ))),"") | G17: =IFERROR( IF(ISNUMBER(FIND("T2",B17)),220, IF(ISNUMBER(FIND("T4",B17)),440, IF(ISNUMBER(FIND("T5",B17)),575, IF(ISNUMBER(FIND("T6",B17)),690,"")))), "") -> 575
... A37: 13392766 | B37: =VLOOKUP(A37,Planilha2!B:C,2,0) -> INVERSOR MSCFW110088T4OFAYWZ-UI | C37: F13 | D37: =VLOOKUP(A37,Planilha2!B:H,7,0) -> LINHA M3 | E37: 32600 | F37: =IFERROR( IF(ISNUMBER(FIND("CFW110",B37)), VALUE(MID(B37,FIND("CFW110",B37)+6,FIND("T",B37,FIND("CFW110",B37))-(FIND("CFW110",B37)+6))), IF(ISNUMBER(FIND("D",B37)), VALUE(SUBSTITUTE(MID(B37,FIND("D",B37)+1,FIND("T",B37,FIND("D",B37))-(FIND("D",B37)+1)),"P",",")), IF(ISNUMBER(FIND("CFW5",B37)), VALUE(MID(B37, IF(ISNUMBER(FIND("F",B37)),FIND("F",B37)+1,FIND("G",B37)+1), FIND("T",B37)-(IF(ISNUMBER(FIND("F",B37)),FIND("F",B37)+1,FIND("G",B37)+1)) )), VALUE(MID(B37,FIND("E0",B37)+2,FIND("T",B37,FIND("E0",B37))-(FIND("E0",B37)+2))) ))),"") -> 88 | G37: =IFERROR( IF(ISNUMBER(FIND("T2",B37)),220, IF(ISNUMBER(FIND("T4",B37)),440, IF(ISNUMBER(FIND("T5",B37)),575, IF(ISNUMBER(FIND("T6",B37)),690,"")))), "") -> 440
A38: 13418344 | B38: =VLOOKUP(A38,Planilha2!B:C,2,0) -> INVERSOR BRCFW110088T4OFAS7Z | C38: F13 | D38: =VLOOKUP(A38,Planilha2!B:H,7,0) -> LINHA M3 | E38: 0,000 | F38: =IFERROR( IF(ISNUMBER(FIND("CFW110",B38)), VALUE(MID(B38,FIND("CFW110",B38)+6,FIND("T",B38,FIND("CFW110",B38))-(FIND("CFW110",B38)+6))), IF(ISNUMBER(FIND("D",B38)), VALUE(SUBSTITUTE(MID(B38,FIND("D",B38)+1,FIND("T",B38,FIND("D",B38))-(FIND("D",B38)+1)),"P",",")), IF(ISNUMBER(FIND("CFW5",B38)), VALUE(MID(B38, IF(ISNUMBER(FIND("F",B38)),FIND("F",B38)+1,FIND("G",B38)+1), FIND("T",B38)-(IF(ISNUMBER(FIND("F",B38)),FIND("F",B38)+1,FIND("G",B38)+1)) )), VALUE(MID(B38,FIND("E0",B38)+2,FIND("T",B38,FIND("E0",B38))-(FIND("E0",B38)+2))) ))),"") -> 88 | G38: =IFERROR( IF(ISNUMBER(FIND("T2",B38)),220, IF(ISNUMBER(FIND("T4",B38)),440, IF(ISNUMBER(FIND("T5",B38)),575, IF(ISNUMBER(FIND("T6",B38)),690,"")))), "") -> 440
A39: 13446552 | B39: =VLOOKUP(A39,Planilha2!B:C,2,0) -> INVERSOR SACFW110027T5ONFYZ | C39: F13 | D39: =VLOOKUP(A39,Planilha2!B:H,7,0) -> LINHA M1 | E39: 26260 | F39: =IFERROR( IF(ISNUMBER(FIND("CFW110",B39)), VALUE(MID(B39,FIND("CFW110",B39)+6,FIND("T",B39,FIND("CFW110",B39))-(FIND("CFW110",B39)+6))), IF(ISNUMBER(FIND("D",B39)), VALUE(SUBSTITUTE(MID(B39,FIND("D",B39)+1,FIND("T",B39,FIND("D",B39))-(FIND("D",B39)+1)),"P",",")), IF(ISNUMBER(FIND("CFW5",B39)), VALUE(MID(B39, IF(ISNUMBER(FIND("F",B39)),FIND("F",B39)+1,FIND("G",B39)+1), FIND("T",B39)-(IF(ISNUMBER(FIND("F",B39)),FIND("F",B39)+1,FIND("G",B39)+1)) )), VALUE(MID(B39,FIND("E0",B39)+2,FIND("T",B39,FIND("E0",B39))-(FIND("E0",B39)+2))) ))),"") -> 27 | G39: =IFERROR( IF(ISNUMBER(FIND("T2",B39)),220, IF(ISNUMBER(FIND("T4",B39)),440, IF(ISNUMBER(FIND("T5",B39)),575, IF(ISNUMBER(FIND("T6",B39)),690,"")))), "") -> 575
A40: 13447956 | B40: =VLOOKUP(A40,Planilha2!B:C,2,0) -> INVERSOR SACFW110022T5ONFYZ | C40: F13 | D40: =VLOOKUP(A40,Planilha2!B:H,7,0) -> LINHA M1 | E40: 26260 | F40: =IFERROR( IF(ISNUMBER(FIND("CFW110",B40)), VALUE(MID(B40,FIND("CFW110",B40)+6,FIND("T",B40,FIND("CFW110",B40))-(FIND("CFW110",B40)+6))), IF(ISNUMBER(FIND("D",B40)), VALUE(SUBSTITUTE(MID(B40,FIND("D",B40)+1,FIND("T",B40,FIND("D",B40))-(FIND("D",B40)+1)),"P",",")), IF(ISNUMBER(FIND("CFW5",B40)), VALUE(MID(B40, IF(ISNUMBER(FIND("F",B40)),FIND("F",B40)+1,FIND("G",B40)+1), FIND("T",B40)-(IF(ISNUMBER(FIND("F",B40)),FIND("F",B40)+1,FIND("G",B40)+1)) )), VALUE(MID(B40,FIND("E0",B40)+2,FIND("T",B40,FIND("E0",B40))-(FIND("E0",B40)+2))) ))),"") -> 22 | G40: =IFERROR( IF(ISNUMBER(FIND("T2",B40)),220, IF(ISNUMBER(FIND("T4",B40)),440, IF(ISNUMBER(FIND("T5",B40)),575, IF(ISNUMBER(FIND("T6",B40)),690,"")))), "") -> 575
A41: 13448072 | B41: =VLOOKUP(A41,Planilha2!B:C,2,0) -> INVERSOR SACFW110044T5ONFYZ | C41: F13 | D41: =VLOOKUP(A41,Planilha2!B:H,7,0) -> LINHA M1 | E41: 26260 | F41: =IFERROR( IF(ISNUMBER(FIND("CFW110",B41)), VALUE(MID(B41,FIND("CFW110",B41)+6,FIND("T",B41,FIND("CFW110",B41))-(FIND("CFW110",B41)+6))), IF(ISNUMBER(FIND("D",B41)), VALUE(SUBSTITUTE(MID(B41,FIND("D",B41)+1,FIND("T",B41,FIND("D",B41))-(FIND("D",B41)+1)),"P",",")), IF(ISNUMBER(FIND("CFW5",B41)), VALUE(MID(B41, IF(ISNUMBER(FIND("F",B41)),FIND("F",B41)+1,FIND("G",B41)+1), FIND("T",B41)-(IF(ISNUMBER(FIND("F",B41)),FIND("F",B41)+1,FIND("G",B41)+1)) )), VALUE(MID(B41,FIND("E0",B41)+2,FIND("T",B41,FIND("E0",B41))-(FIND("E0",B41)+2))) ))),"") -> 44 | G41: =IFERROR( IF(ISNUMBER(FIND("T2",B41)),220, IF(ISNUMBER(FIND("T4",B41)),440, IF(ISNUMBER(FIND("T5",B41)),575, IF(ISNUMBER(FIND("T6",B41)),690,"")))), "") -> 575
A42: 13448069 | B42: =VLOOKUP(A42,Planilha2!B:C,2,0) -> INVERSOR SACFW110032T5ONFYZ | C42: F13 | D42: =VLOOKUP(A42,Planilha2!B:H,7,0) -> LINHA M1 | E42: 26260 | F42: =IFERROR( IF(ISNUMBER(FIND("CFW110",B42)), VALUE(MID(B42,FIND("CFW110",B42)+6,FIND("T",B42,FIND("CFW110",B42))-(FIND("CFW110",B42)+6))), IF(ISNUMBER(FIND("D",B42)), VALUE(SUBSTITUTE(MID(B42,FIND("D",B42)+1,FIND("T",B42,FIND("D",B42))-(FIND("D",B42)+1)),"P",",")), IF(ISNUMBER(FIND("CFW5",B42)), VALUE(MID(B42, IF(ISNUMBER(FIND("F",B42)),FIND("F",B42)+1,FIND("G",B42)+1), FIND("T",B42)-(IF(ISNUMBER(FIND("F",B42)),FIND("F",B42)+1,FIND("G",B42)+1)) )), VALUE(MID(B42,FIND("E0",B42)+2,FIND("T",B42,FIND("E0",B42))-(FIND("E0",B42)+2))) ))),"") -> 32 | G42: =IFERROR( IF(ISNUMBER(FIND("T2",B42)),220, IF(ISNUMBER(FIND("T4",B42)),440, IF(ISNUMBER(FIND("T5",B42)),575, IF(ISNUMBER(FIND("T6",B42)),690,"")))), "") -> 575
A43: 11988664 | B43: =VLOOKUP(A43,Planilha2!B:C,2,0) -> INVERSOR SACFW110044T6OYZ | C43: F13 | D43: =VLOOKUP(A43,Planilha2!B:H,7,0) -> LINHA M3 | E43: 31762 | F43: =IFERROR( IF(ISNUMBER(FIND("CFW110",B43)), VALUE(MID(B43,FIND("CFW110",B43)+6,FIND("T",B43,FIND("CFW110",B43))-(FIND("CFW110",B43)+6))), IF(ISNUMBER(FIND("D",B43)), VALUE(SUBSTITUTE(MID(B43,FIND("D",B43)+1,FIND("T",B43,FIND("D",B43))-(FIND("D",B43)+1)),"P",",")), IF(ISNUMBER(FIND("CFW5",B43)), VALUE(MID(B43, IF(ISNUMBER(FIND("F",B43)),FIND("F",B43)+1,FIND("G",B43)+1), FIND("T",B43)-(IF(ISNUMBER(FIND("F",B43)),FIND("F",B43)+1,FIND("G",B43)+1)) )), VALUE(MID(B43,FIND("E0",B43)+2,FIND("T",B43,FIND("E0",B43))-(FIND("E0",B43)+2))) ))),"") -> 44 | G43: =IFERROR( IF(ISNUMBER(FIND("T2",B43)),220, IF(ISNUMBER(FIND("T4",B43)),440, IF(ISNUMBER(FIND("T5",B43)),575, IF(ISNUMBER(FIND("T6",B43)),690,"")))), "") -> 690
A44: 13474402 | B44: =VLOOKUP(A44,Planilha2!B:C,2,0) -> INVERSOR BRCFW110045T2OSWZ | C44: F13 | D44: =VLOOKUP(A44,Planilha2!B:H,7,0) -> LINHA M1 | E44: 26360 | F44: =IFERROR( IF(ISNUMBER(FIND("CFW110",B44)), VALUE(MID(B44,FIND("CFW110",B44)+6,FIND("T",B44,FIND("CFW110",B44))-(FIND("CFW110",B44)+6))), IF(ISNUMBER(FIND("D",B44)), VALUE(SUBSTITUTE(MID(B44,FIND("D",B44)+1,FIND("T",B44,FIND("D",B44))-(FIND("D",B44)+1)),"P",",")), IF(ISNUMBER(FIND("CFW5",B44)), VALUE(MID(B44, IF(ISNUMBER(FIND("F",B44)),FIND("F",B44)+1,FIND("G",B44)+1), FIND("T",B44)-(IF(ISNUMBER(FIND("F",B44)),FIND("F",B44)+1,FIND("G",B44)+1)) )), VALUE(MID(B44,FIND("E0",B44)+2,FIND("T",B44,FIND("E0",B44))-(FIND("E0",B44)+2))) ))),"") -> 45 | G44: =IFERROR( IF(ISNUMBER(FIND("T2",B44)),220, IF(ISNUMBER(FIND("T4",B44)),440, IF(ISNUMBER(FIND("T5",B44)),575, IF(ISNUMBER(FIND("T6",B44)),690,"")))), "") -> 220
A45: 13498395 | B45: =VLOOKUP(A45,Planilha2!B:C,2,0) -> INVERSOR CFW700D88P0T4DBN1Y1-UI | C45: F13 | D45: =VLOOKUP(A45,Planilha2!B:H,7,0) -> LINHA M3 | E45: 31100 | F45: =IFERROR( IF(ISNUMBER(FIND("CFW110",B45)), VALUE(MID(B45,FIND("CFW110",B45)+6,FIND("T",B45,FIND("CFW110",B45))-(FIND("CFW110",B45)+6))), IF(ISNUMBER(FIND("D",B45)), VALUE(SUBSTITUTE(MID(B45,FIND("D",B45)+1,FIND("T",B45,FIND("D",B45))-(FIND("D",B45)+1)),"P",",")), IF(ISNUMBER(FIND("CFW5",B45)), VALUE(MID(B45, IF(ISNUMBER(FIND("F",B45)),FIND("F",B45)+1,FIND("G",B45)+1), FIND("T",B45)-(IF(ISNUMBER(FIND("F",B45)),FIND("F",B45)+1,FIND("G",B45)+1)) )), VALUE(MID(B45,FIND("E0",B45)+2,FIND("T",B45,FIND("E0",B45))-(FIND("E0",B45)+2))) ))),"") -> 88 | G45: =IFERROR( IF(ISNUMBER(FIND("T2",B45)),220, IF(ISNUMBER(FIND("T4",B45)),440, IF(ISNUMBER(FIND("T5",B45)),575, IF(ISNUMBER(FIND("T6",B45)),690,"")))), "") -> 440
A46: 13511209 | B46: =VLOOKUP(A46,Planilha2!B:C,2,0) -> INVERSOR BRCFW110058T4OWS7Z | C46: F13 | D46: =VLOOKUP(A46,Planilha2!B:H,7,0) -> LINHA M3 | E46: 20870 | F46: =IFERROR( IF(ISNUMBER(FIND("CFW110",B46)), VALUE(MID(B46,FIND("CFW110",B46)+6,FIND("T",B46,FIND("CFW110",B46))-(FIND("CFW110",B46)+6))), IF(ISNUMBER(FIND("D",B46)), VALUE(SUBSTITUTE(MID(B46,FIND("D",B46)+1,FIND("T",B46,FIND("D",B46))-(FIND("D",B46)+1)),"P",",")), IF(ISNUMBER(FIND("CFW5",B46)), VALUE(MID(B46, IF(ISNUMBER(FIND("F",B46)),FIND("F",B46)+1,FIND("G",B46)+1), FIND("T",B46)-(IF(ISNUMBER(FIND("F",B46)),FIND("F",B46)+1,FIND("G",B46)+1)) )), VALUE(MID(B46,FIND("E0",B46)+2,FIND("T",B46,FIND("E0",B46))-(FIND("E0",B46)+2))) ))),"") -> 58 | G46: =IFERROR( IF(ISNUMBER(FIND("T2",B46)),220, IF(ISNUMBER(FIND("T4",B46)),440, IF(ISNUMBER(FIND("T5",B46)),575, IF(ISNUMBER(FIND("T6",B46)),690,"")))), "") -> 440
A47: 13509572 | B47: =VLOOKUP(A47,Planilha2!B:C,2,0) -> INVERSOR BRCFW110088T4OWS7Z | C47: F13 | D47: =VLOOKUP(A47,Planilha2!B:H,7,0) -> LINHA M3 | E47: 33200 | F47: =IFERROR( IF(ISNUMBER(FIND("CFW110",B47)), VALUE(MID(B47,FIND("CFW110",B47)+6,FIND("T",B47,FIND("CFW110",B47))-(FIND("CFW110",B47)+6))), IF(ISNUMBER(FIND("D",B47)), VALUE(SUBSTITUTE(MID(B47,FIND("D",B47)+1,FIND("T",B47,FIND("D",B47))-(FIND("D",B47)+1)),"P",",")), IF(ISNUMBER(FIND("CFW5",B47)), VALUE(MID(B47, IF(ISNUMBER(FIND("F",B47)),FIND("F",B47)+1,FIND("G",B47)+1), FIND("T",B47)-(IF(ISNUMBER(FIND("F",B47)),FIND("F",B47)+1,FIND("G",B47)+1)) )), VALUE(MID(B47,FIND("E0",B47)+2,FIND("T",B47,FIND("E0",B47))-(FIND("E0",B47)+2))) ))),"") -> 88 | G47: =IFERROR( IF(ISNUMBER(FIND("T2",B47)),220, IF(ISNUMBER(FIND("T4",B47)),440, IF(ISNUMBER(FIND("T5",B47)),575, IF(ISNUMBER(FIND("T6",B47)),690,"")))), "") -> 440
A48: 13511023 | B48: =VLOOKUP(A48,Planilha2!B:C,2,0) -> INVERSOR CFW700D70P5T4DBN1Y1-UI | C48: F13 | D48: =VLOOKUP(A48,Planilha2!B:H,7,0) -> LINHA M3 | E48: 26392 | F48: =IFERROR( IF(ISNUMBER(FIND("CFW110",B48)), VALUE(MID(B48,FIND("CFW110",B48)+6,FIND("T",B48,FIND("CFW110",B48))-(FIND("CFW110",B48)+6))), IF(ISNUMBER(FIND("D",B48)), VALUE(SUBSTITUTE(MID(B48,FIND("D",B48)+1,FIND("T",B48,FIND("D",B48))-(FIND("D",B48)+1)),"P",",")), IF(ISNUMBER(FIND("CFW5",B48)), VALUE(MID(B48, IF(ISNUMBER(FIND("F",B48)),FIND("F",B48)+1,FIND("G",B48)+1), FIND("T",B48)-(IF(ISNUMBER(FIND("F",B48)),FIND("F",B48)+1,FIND("G",B48)+1)) )), VALUE(MID(B48,FIND("E0",B48)+2,FIND("T",B48,FIND("E0",B48))-(FIND("E0",B48)+2))) ))),"") -> 70.5 | G48: =IFERROR( IF(ISNUMBER(FIND("T2",B48)),220, IF(ISNUMBER(FIND("T4",B48)),440, IF(ISNUMBER(FIND("T5",B48)),575, IF(ISNUMBER(FIND("T6",B48)),690,"")))), "") -> 440
A49: 13509423 | B49: =VLOOKUP(A49,Planilha2!B:C,2,0) -> INVERSOR BRCFW110070T4OFAYZ-UI | C49: F13 | D49: =VLOOKUP(A49,Planilha2!B:H,7,0) -> LINHA M3 | E49: 31100 | F49: =IFERROR( IF(ISNUMBER(FIND("CFW110",B49)), VALUE(MID(B49,FIND("CFW110",B49)+6,FIND("T",B49,FIND("CFW110",B49))-(FIND("CFW110",B49)+6))), IF(ISNUMBER(FIND("D",B49)), VALUE(SUBSTITUTE(MID(B49,FIND("D",B49)+1,FIND("T",B49,FIND("D",B49))-(FIND("D",B49)+1)),"P",",")), IF(ISNUMBER(FIND("CFW5",B49)), VALUE(MID(B49, IF(ISNUMBER(FIND("F",B49)),FIND("F",B49)+1,FIND("G",B49)+1), FIND("T",B49)-(IF(ISNUMBER(FIND("F",B49)),FIND("F",B49)+1,FIND("G",B49)+1)) )), VALUE(MID(B49,FIND("E0",B49)+2,FIND("T",B49,FIND("E0",B49))-(FIND("E0",B49)+2))) ))),"") -> 70 | G49: =IFERROR( IF(ISNUMBER(FIND("T2",B49)),220, IF(ISNUMBER(FIND("T4",B49)),440, IF(ISNUMBER(FIND("T5",B49)),575, IF(ISNUMBER(FIND("T6",B49)),690,"")))), "") -> 440
A50: 13509573 | B50: =VLOOKUP(A50,Planilha2!B:C,2,0) -> INVERSOR BRCFW110088T4OWS7Z-UI | C50: F13 | D50: =VLOOKUP(A50,Planilha2!B:H,7,0) -> LINHA M3 | E50: 33200 | F50: =IFERROR( IF(ISNUMBER(FIND("CFW110",B50)), VALUE(MID(B50,FIND("CFW110",B50)+6,FIND("T",B50,FIND("CFW110",B50))-(FIND("CFW110",B50)+6))), IF(ISNUMBER(FIND("D",B50)), VALUE(SUBSTITUTE(MID(B50,FIND("D",B50)+1,FIND("T",B50,FIND("D",B50))-(FIND("D",B50)+1)),"P",",")), IF(ISNUMBER(FIND("CFW5",B50)), VALUE(MID(B50, IF(ISNUMBER(FIND("F",B50)),FIND("F",B50)+1,FIND("G",B50)+1), FIND("T",B50)-(IF(ISNUMBER(FIND("F",B50)),FIND("F",B50)+1,FIND("G",B50)+1)) )), VALUE(MID(B50,FIND("E0",B50)+2,FIND("T",B50,FIND("E0",B50))-(FIND("E0",B50)+2))) ))),"") -> 88 | G50: =IFERROR( IF(ISNUMBER(FIND("T2",B50)),220, IF(ISNUMBER(FIND("T4",B50)),440, IF(ISNUMBER(FIND("T5",B50)),575, IF(ISNUMBER(FIND("T6",B50)),690,"")))), "") -> 440
... A60: 13539762 | B60: =VLOOKUP(A60,Planilha2!B:C,2,0) -> INVERSOR CFW700D70P5T4DBN1C3-UI | C60: F13 | D60: =VLOOKUP(A60,Planilha2!B:H,7,0) -> LINHA M3 | E60: 26291 | F60: =IFERROR( IF(ISNUMBER(FIND("CFW110",B60)), VALUE(MID(B60,FIND("CFW110",B60)+6,FIND("T",B60,FIND("CFW110",B60))-(FIND("CFW110",B60)+6))), IF(ISNUMBER(FIND("D",B60)), VALUE(SUBSTITUTE(MID(B60,FIND("D",B60)+1,FIND("T",B60,FIND("D",B60))-(FIND("D",B60)+1)),"P",",")), IF(ISNUMBER(FIND("CFW5",B60)), VALUE(MID(B60, IF(ISNUMBER(FIND("F",B60)),FIND("F",B60)+1,FIND("G",B60)+1), FIND("T",B60)-(IF(ISNUMBER(FIND("F",B60)),FIND("F",B60)+1,FIND("G",B60)+1)) )), VALUE(MID(B60,FIND("E0",B60)+2,FIND("T",B60,FIND("E0",B60))-(FIND("E0",B60)+2))) ))),"") -> 70.5 | G60: =IFERROR( IF(ISNUMBER(FIND("T2",B60)),220, IF(ISNUMBER(FIND("T4",B60)),440, IF(ISNUMBER(FIND("T5",B60)),575, IF(ISNUMBER(FIND("T6",B60)),690,"")))), "") -> 440
A61: 13539793 | B61: =VLOOKUP(A61,Planilha2!B:C,2,0) -> INVERSOR BRCFW110070T4OFAS7Z | C61: F13 | D61: =VLOOKUP(A61,Planilha2!B:H,7,0) -> LINHA M3 | E61: 0,000 | F61: =IFERROR( IF(ISNUMBER(FIND("CFW110",B61)), VALUE(MID(B61,FIND("CFW110",B61)+6,FIND("T",B61,FIND("CFW110",B61))-(FIND("CFW110",B61)+6))), IF(ISNUMBER(FIND("D",B61)), VALUE(SUBSTITUTE(MID(B61,FIND("D",B61)+1,FIND("T",B61,FIND("D",B61))-(FIND("D",B61)+1)),"P",",")), IF(ISNUMBER(FIND("CFW5",B61)), VALUE(MID(B61, IF(ISNUMBER(FIND("F",B61)),FIND("F",B61)+1,FIND("G",B61)+1), FIND("T",B61)-(IF(ISNUMBER(FIND("F",B61)),FIND("F",B61)+1,FIND("G",B61)+1)) )), VALUE(MID(B61,FIND("E0",B61)+2,FIND("T",B61,FIND("E0",B61))-(FIND("E0",B61)+2))) ))),"") -> 70 | G61: =IFERROR( IF(ISNUMBER(FIND("T2",B61)),220, IF(ISNUMBER(FIND("T4",B61)),440, IF(ISNUMBER(FIND("T5",B61)),575, IF(ISNUMBER(FIND("T6",B61)),690,"")))), "") -> 440
A62: 13558081 | B62: =VLOOKUP(A62,Planilha2!B:C,2,0) -> INVERSOR CFW700D70P5T4DBN1C3Y1-UI | C62: F13 | D62: =VLOOKUP(A62,Planilha2!B:H,7,0) -> LINHA M3 | E62: 26381 | F62: =IFERROR( IF(ISNUMBER(FIND("CFW110",B62)), VALUE(MID(B62,FIND("CFW110",B62)+6,FIND("T",B62,FIND("CFW110",B62))-(FIND("CFW110",B62)+6))), IF(ISNUMBER(FIND("D",B62)), VALUE(SUBSTITUTE(MID(B62,FIND("D",B62)+1,FIND("T",B62,FIND("D",B62))-(FIND("D",B62)+1)),"P",",")), IF(ISNUMBER(FIND("CFW5",B62)), VALUE(MID(B62, IF(ISNUMBER(FIND("F",B62)),FIND("F",B62)+1,FIND("G",B62)+1), FIND("T",B62)-(IF(ISNUMBER(FIND("F",B62)),FIND("F",B62)+1,FIND("G",B62)+1)) )), VALUE(MID(B62,FIND("E0",B62)+2,FIND("T",B62,FIND("E0",B62))-(FIND("E0",B62)+2))) ))),"") -> 70.5 | G62: =IFERROR( IF(ISNUMBER(FIND("T2",B62)),220, IF(ISNUMBER(FIND("T4",B62)),440, IF(ISNUMBER(FIND("T5",B62)),575, IF(ISNUMBER(FIND("T6",B62)),690,"")))), "") -> 440
A63: 13505079 | B63: =VLOOKUP(A63,Planilha2!B:C,2,0) -> INVERSOR BRCFW110045T2OSVZ | C63: F13 | D63: =VLOOKUP(A63,Planilha2!B:H,7,0) -> LINHA M1 | E63: 15600 | F63: =IFERROR( IF(ISNUMBER(FIND("CFW110",B63)), VALUE(MID(B63,FIND("CFW110",B63)+6,FIND("T",B63,FIND("CFW110",B63))-(FIND("CFW110",B63)+6))), IF(ISNUMBER(FIND("D",B63)), VALUE(SUBSTITUTE(MID(B63,FIND("D",B63)+1,FIND("T",B63,FIND("D",B63))-(FIND("D",B63)+1)),"P",",")), IF(ISNUMBER(FIND("CFW5",B63)), VALUE(MID(B63, IF(ISNUMBER(FIND("F",B63)),FIND("F",B63)+1,FIND("G",B63)+1), FIND("T",B63)-(IF(ISNUMBER(FIND("F",B63)),FIND("F",B63)+1,FIND("G",B63)+1)) )), VALUE(MID(B63,FIND("E0",B63)+2,FIND("T",B63,FIND("E0",B63))-(FIND("E0",B63)+2))) ))),"") -> 45 | G63: =IFERROR( IF(ISNUMBER(FIND("T2",B63)),220, IF(ISNUMBER(FIND("T4",B63)),440, IF(ISNUMBER(FIND("T5",B63)),575, IF(ISNUMBER(FIND("T6",B63)),690,"")))), "") -> 220
A64: 13505080 | B64: =VLOOKUP(A64,Planilha2!B:C,2,0) -> INVERSOR BRCFW110054T2OSVZ | C64: F13 | D64: =VLOOKUP(A64,Planilha2!B:H,7,0) -> LINHA M1 | E64: 16000 | F64: =IFERROR( IF(ISNUMBER(FIND("CFW110",B64)), VALUE(MID(B64,FIND("CFW110",B64)+6,FIND("T",B64,FIND("CFW110",B64))-(FIND("CFW110",B64)+6))), IF(ISNUMBER(FIND("D",B64)), VALUE(SUBSTITUTE(MID(B64,FIND("D",B64)+1,FIND("T",B64,FIND("D",B64))-(FIND("D",B64)+1)),"P",",")), IF(ISNUMBER(FIND("CFW5",B64)), VALUE(MID(B64, IF(ISNUMBER(FIND("F",B64)),FIND("F",B64)+1,FIND("G",B64)+1), FIND("T",B64)-(IF(ISNUMBER(FIND("F",B64)),FIND("F",B64)+1,FIND("G",B64)+1)) )), VALUE(MID(B64,FIND("E0",B64)+2,FIND("T",B64,FIND("E0",B64))-(FIND("E0",B64)+2))) ))),"") -> 54 | G64: =IFERROR( IF(ISNUMBER(FIND("T2",B64)),220, IF(ISNUMBER(FIND("T4",B64)),440, IF(ISNUMBER(FIND("T5",B64)),575, IF(ISNUMBER(FIND("T6",B64)),690,"")))), "") -> 220
A65: 13505081 | B65: =VLOOKUP(A65,Planilha2!B:C,2,0) -> INVERSOR BRCFW110070T2OSVZ | C65: F13 | D65: =VLOOKUP(A65,Planilha2!B:H,7,0) -> LINHA M1 | E65: 17900 | F65: =IFERROR( IF(ISNUMBER(FIND("CFW110",B65)), VALUE(MID(B65,FIND("CFW110",B65)+6,FIND("T",B65,FIND("CFW110",B65))-(FIND("CFW110",B65)+6))), IF(ISNUMBER(FIND("D",B65)), VALUE(SUBSTITUTE(MID(B65,FIND("D",B65)+1,FIND("T",B65,FIND("D",B65))-(FIND("D",B65)+1)),"P",",")), IF(ISNUMBER(FIND("CFW5",B65)), VALUE(MID(B65, IF(ISNUMBER(FIND("F",B65)),FIND("F",B65)+1,FIND("G",B65)+1), FIND("T",B65)-(IF(ISNUMBER(FIND("F",B65)),FIND("F",B65)+1,FIND("G",B65)+1)) )), VALUE(MID(B65,FIND("E0",B65)+2,FIND("T",B65,FIND("E0",B65))-(FIND("E0",B65)+2))) ))),"") -> 70 | G65: =IFERROR( IF(ISNUMBER(FIND("T2",B65)),220, IF(ISNUMBER(FIND("T4",B65)),440, IF(ISNUMBER(FIND("T5",B65)),575, IF(ISNUMBER(FIND("T6",B65)),690,"")))), "") -> 220
A66: 13505082 | B66: =VLOOKUP(A66,Planilha2!B:C,2,0) -> INVERSOR BRCFW110086T2OSVZ | C66: F13 | D66: =VLOOKUP(A66,Planilha2!B:H,7,0) -> LINHA M3 | E66: 29500 | F66: =IFERROR( IF(ISNUMBER(FIND("CFW110",B66)), VALUE(MID(B66,FIND("CFW110",B66)+6,FIND("T",B66,FIND("CFW110",B66))-(FIND("CFW110",B66)+6))), IF(ISNUMBER(FIND("D",B66)), VALUE(SUBSTITUTE(MID(B66,FIND("D",B66)+1,FIND("T",B66,FIND("D",B66))-(FIND("D",B66)+1)),"P",",")), IF(ISNUMBER(FIND("CFW5",B66)), VALUE(MID(B66, IF(ISNUMBER(FIND("F",B66)),FIND("F",B66)+1,FIND("G",B66)+1), FIND("T",B66)-(IF(ISNUMBER(FIND("F",B66)),FIND("F",B66)+1,FIND("G",B66)+1)) )), VALUE(MID(B66,FIND("E0",B66)+2,FIND("T",B66,FIND("E0",B66))-(FIND("E0",B66)+2))) ))),"") -> 86 | G66: =IFERROR( IF(ISNUMBER(FIND("T2",B66)),220, IF(ISNUMBER(FIND("T4",B66)),440, IF(ISNUMBER(FIND("T5",B66)),575, IF(ISNUMBER(FIND("T6",B66)),690,"")))), "") -> 220
A67: 13505083 | B67: =VLOOKUP(A67,Planilha2!B:C,2,0) -> INVERSOR BRCFW110105T2OSVZ | C67: F13 | D67: =VLOOKUP(A67,Planilha2!B:H,7,0) -> LINHA M3 | E67: 31400 | F67: =IFERROR( IF(ISNUMBER(FIND("CFW110",B67)), VALUE(MID(B67,FIND("CFW110",B67)+6,FIND("T",B67,FIND("CFW110",B67))-(FIND("CFW110",B67)+6))), IF(ISNUMBER(FIND("D",B67)), VALUE(SUBSTITUTE(MID(B67,FIND("D",B67)+1,FIND("T",B67,FIND("D",B67))-(FIND("D",B67)+1)),"P",",")), IF(ISNUMBER(FIND("CFW5",B67)), VALUE(MID(B67, IF(ISNUMBER(FIND("F",B67)),FIND("F",B67)+1,FIND("G",B67)+1), FIND("T",B67)-(IF(ISNUMBER(FIND("F",B67)),FIND("F",B67)+1,FIND("G",B67)+1)) )), VALUE(MID(B67,FIND("E0",B67)+2,FIND("T",B67,FIND("E0",B67))-(FIND("E0",B67)+2))) ))),"") -> 105 | G67: =IFERROR( IF(ISNUMBER(FIND("T2",B67)),220, IF(ISNUMBER(FIND("T4",B67)),440, IF(ISNUMBER(FIND("T5",B67)),575, IF(ISNUMBER(FIND("T6",B67)),690,"")))), "") -> 220
A68: 13505408 | B68: =VLOOKUP(A68,Planilha2!B:C,2,0) -> INVERSOR BRCFW110088T4OSVZ | C68: F13 | D68: =VLOOKUP(A68,Planilha2!B:H,7,0) -> LINHA M3 | E68: 32600 | F68: =IFERROR( IF(ISNUMBER(FIND("CFW110",B68)), VALUE(MID(B68,FIND("CFW110",B68)+6,FIND("T",B68,FIND("CFW110",B68))-(FIND("CFW110",B68)+6))), IF(ISNUMBER(FIND("D",B68)), VALUE(SUBSTITUTE(MID(B68,FIND("D",B68)+1,FIND("T",B68,FIND("D",B68))-(FIND("D",B68)+1)),"P",",")), IF(ISNUMBER(FIND("CFW5",B68)), VALUE(MID(B68, IF(ISNUMBER(FIND("F",B68)),FIND("F",B68)+1,FIND("G",B68)+1), FIND("T",B68)-(IF(ISNUMBER(FIND("F",B68)),FIND("F",B68)+1,FIND("G",B68)+1)) )), VALUE(MID(B68,FIND("E0",B68)+2,FIND("T",B68,FIND("E0",B68))-(FIND("E0",B68)+2))) ))),"") -> 88 | G68: =IFERROR( IF(ISNUMBER(FIND("T2",B68)),220, IF(ISNUMBER(FIND("T4",B68)),440, IF(ISNUMBER(FIND("T5",B68)),575, IF(ISNUMBER(FIND("T6",B68)),690,"")))), "") -> 440
...

Sheet Planilha2
A1: Cen. | B1: Material | C1: TxtBreveMaterial | D1: TMat | E1: Dpst | F1: DpSuE | G1: PlMRP | H1: Nome | I1: R | J1: SuE | K1: Perfil | L1: Estq.segurança | M1: TipSupr. | N1: L | O1: TamanhMínLot | P1: Tam.máx.lote | Q1: ValArredond.
A2: 1320 | B2: 10193860 | C2: INVERSOR BRCFW110045T2SZ | D2: FERT | E2: FA01 | F2: FA01 | G2: 072 | H2: LINHA M1 | K2: ZWEG | L2: 0 | M2: E | O2: 1 | P2: 4 | Q2: 1
A3: 1320 | B3: 10193861 | C3: INVERSOR BRCFW110054T2SZ | D3: FERT | E3: FA01 | F3: FA01 | G3: 072 | H3: LINHA M1 | K3: ZWEG | L3: 0 | M3: E | O3: 1 | P3: 4 | Q3: 1
A4: 1320 | B4: 10193862 | C4: INVERSOR BRCFW110070T2SZ | D4: FERT | E4: FA01 | F4: FA01 | G4: 072 | H4: LINHA M1 | K4: ZWEG | L4: 0 | M4: E | O4: 1 | P4: 4 | Q4: 1
A5: 1320 | B5: 10193863 | C5: INVERSOR BRCFW110013T4SZ | D5: FERT | E5: FA01 | F5: FA01 | G5: 051 | H5: LINHA P5 | K5: ZWEG | L5: 0 | M5: E | O5: 1 | P5: 8 | Q5: 1
A6: 1320 | B6: 10193864 | C6: INVERSOR BRCFW110038T4SZ | D6: FERT | E6: FA01 | F6: FA01 | G6: 072 | H6: LINHA M1 | K6: ZWEG | L6: 0 | M6: E | O6: 1 | P6: 4 | Q6: 1
A7: 1320 | B7: 10193865 | C7: INVERSOR BRCFW110045T4SZ | D7: FERT | E7: FA01 | F7: FA01 | G7: 072 | H7: LINHA M1 | K7: ZWEG | L7: 0 | M7: E | O7: 1 | P7: 4 | Q7: 1
A8: 1320 | B8: 10193866 | C8: INVERSOR BRCFW110058T4SZ | D8: FERT | E8: FA01 | F8: FA01 | G8: 072 | H8: LINHA M1 | K8: ZWEG | L8: 0 | M8: E | O8: 1 | P8: 4 | Q8: 1
A9: 1320 | B9: 10193867 | C9: INVERSOR BRCFW110070T4SZ | D9: FERT | E9: FA01 | F9: FA01 | G9: 073 | H9: LINHA M3 | K9: ZWEG | L9: 0 | M9: E | O9: 1 | P9: 10 | Q9: 1
A10: 1320 | B10: 10193868 | C10: INVERSOR BRCFW110088T4SZ | D10: FERT | E10: FA01 | F10: FA01 | G10: 073 | H10: LINHA M3 | K10: ZWEG | L10: 0 | M10: E | O10: 1 | P10: 10 | Q10: 1
A11: 1320 | B11: 10193872 | C11: INVERSOR BRCFW110070T2OFAZ | D11: FERT | E11: FA01 | F11: FA01 | G11: 072 | H11: LINHA M1 | K11: ZWEG | L11: 0 | M11: E | O11: 1 | P11: 4 | Q11: 1
A12: 1320 | B12: 10193873 | C12: INVERSOR BRCFW110013T4OFAZ | D12: FERT | E12: FA01 | F12: FA01 | G12: 051 | H12: LINHA P5 | K12: ZWEG | L12: 0 | M12: E | O12: 1 | P12: 8 | Q12: 1
A13: 1320 | B13: 10193874 | C13: INVERSOR BRCFW110031T4OFAZ | D13: FERT | E13: FA01 | F13: FA01 | G13: 071 | H13: LINHA P7 | K13: ZWEG | L13: 0 | M13: E | O13: 1 | P13: 8 | Q13: 1
... A2076: 1320 | B2076: 14821623 | C2076: INVERSOR BRCFW110088T4OSSZ | D2076: FERT | E2076: FA01 | F2076: FA01 | G2076: 073 | H2076: LINHA M3 | K2076: ZWEG | L2076: 0 | M2076: E | O2076: 1 | P2076: 10 | Q2076: 1
A2077: 1320 | B2077: 14837150 | C2077: INVERSOR BRCFW110024T2OFAECZ | D2077: FERT | E2077: FA01 | G2077: 071 | H2077: LINHA P7 | K2077: ZWEG | L2077: 0 | M2077: E | O2077: 1 | P2077: 8 | Q2077: 1
A2078: 1320 | B2078: 14837152 | C2078: INVERSOR BRCFW110033T2OFAECZ | D2078: FERT | E2078: FA01 | G2078: 071 | H2078: LINHA P7 | K2078: ZWEG | L2078: 0 | M2078: E | O2078: 0 | P2078: 8 | Q2078: 1
A2079: 1320 | B2079: 14837153 | C2079: INVERSOR BRCFW110070T2OFAECZ | D2079: FERT | E2079: FA01 | G2079: 072 | H2079: LINHA M1 | K2079: ZWEG | L2079: 0 | M2079: E | O2079: 0 | P2079: 3 | Q2079: 0
A2080: 1320 | B2080: 14837156 | C2080: INVERSOR BRCFW110105T2OFAECZ | D2080: FERT | E2080: FA01 | G2080: 073 | H2080: LINHA M3 | K2080: ZWEG | L2080: 0 | M2080: E | O2080: 0 | P2080: 10 | Q2080: 0
A2081: 1320 | B2081: 14837157 | C2081: INVERSOR BRCFW110180T2OECZ | D2081: FERT | E2081: FA01 | G2081: 083 | H2081: LINHA G1 | K2081: ZWEG | L2081: 0 | M2081: E | O2081: 1 | P2081: 2 | Q2081: 1
A2082: 1320 | B2082: 14837178 | C2082: INVERSOR BRCFW110142T2OECZ | D2082: FERT | E2082: FA01 | G2082: 083 | H2082: LINHA G1 | K2082: ZWEG | L2082: 0 | M2082: E | O2082: 1 | P2082: 2 | Q2082: 1
A2083: 1320 | B2083: 14837179 | C2083: INVERSOR BRCFW110142T4OECZ | D2083: FERT | E2083: FA01 | G2083: 083 | H2083: LINHA G1 | K2083: ZWEG | L2083: 0 | M2083: E | O2083: 1 | P2083: 2 | Q2083: 1
A2084: 1320 | B2084: 14837180 | C2084: INVERSOR BRCFW110054T2OFAECZ | D2084: FERT | E2084: FA01 | G2084: 072 | H2084: LINHA M1 | K2084: ZWEG | L2084: 0 | M2084: E | O2084: 0 | P2084: 4 | Q2084: 0
A2085: 1320 | B2085: 14837185 | C2085: INVERSOR BRCFW110086T2OFAECZ | D2085: FERT | E2085: FA01 | G2085: 073 | H2085: LINHA M3 | K2085: ZWEG | L2085: 0 | M2085: E | O2085: 0 | P2085: 10 | Q2085: 0
A2086: 1320 | B2086: 14837186 | C2086: INVERSOR BRCFW110058T4OFAECZ | D2086: FERT | E2086: FA01 | G2086: 072 | H2086: LINHA M1 | K2086: ZWEG | L2086: 0 | M2086: E | O2086: 0 | P2086: 4 | Q2086: 0
A2087: 1320 | B2087: 14837218 | C2087: INVERSOR BRCFW110017T4OFAECZ | D2087: FERT | E2087: FA01 | G2087: 071 | H2087: LINHA P7 | K2087: ZWEG | L2087: 0 | M2087: E | O2087: 0 | P2087: 8 | Q2087: 1
A2088: 1320 | B2088: 14837222 | C2088: INVERSOR BRCFW110038T4OFAECZ | D2088: FERT | E2088: FA01 | G2088: 072 | H2088: LINHA M1 | K2088: ZWEG | L2088: 0 | M2088: E | O2088: 0 | P2088: 4 | Q2088: 0
... A2098: 1320 | B2098: 14882241 | C2098: INVERSOR MSCFW110070T4OFAZ-UI | D2098: HALB | E2098: FA01 | G2098: 073 | H2098: LINHA M3 | K2098: ZWEG | L2098: 0 | M2098: E | O2098: 1 | P2098: 10 | Q2098: 1
A2099: 1320 | B2099: 14888368 | C2099: INVERSOR CFW701A07P0T2DB20C3W1 | D2099: FERT | E2099: FA01 | F2099: FA01 | G2099: 033 | H2099: OBSOLETOS DRIVES | K2099: ZWEG | L2099: 0 | M2099: E | O2099: 1 | P2099: 8 | Q2099: 0
A2100: 1320 | B2100: 14896291 | C2100: INVERSOR BRCFW110058T4OYSKZ | D2100: FERT | E2100: FA01 | F2100: FA01 | G2100: 072 | H2100: LINHA M1 | K2100: ZWEG | L2100: 0 | M2100: E | O2100: 1 | P2100: 4 | Q2100: 1
A2101: 1320 | B2101: 14914236 | C2101: INVERSOR MSCFW110211T4ORBWSQZ | D2101: FERT | E2101: FA01 | G2101: 083 | H2101: LINHA G1 | K2101: ZWEG | L2101: 0 | M2101: E | O2101: 1 | P2101: 1 | Q2101: 1
A2102: 1320 | B2102: 14914273 | C2102: INVERSOR MSCFW110370T4ORBWSQZ | D2102: FERT | E2102: FA01 | G2102: 082 | H2102: LINHA G3 | K2102: ZWEG | L2102: 0 | M2102: E | O2102: 1 | P2102: 2 | Q2102: 1
A2103: 1320 | B2103: 14922220 | C2103: INVERSOR EUCFW110088T4OFAYWZ-UI | D2103: HALB | E2103: FA01 | G2103: 073 | H2103: LINHA M3 | K2103: ZWEG | L2103: 0 | M2103: E | O2103: 0 | P2103: 10 | Q2103: 0
A2104: 1320 | B2104: 14922311 | C2104: INVERSOR EUCFW110105T4OYWZ-UI | D2104: HALB | E2104: FA01 | G2104: 083 | H2104: LINHA G1 | K2104: ZWEG | L2104: 0 | M2104: E | O2104: 1 | P2104: 3 | Q2104: 1
A2105: 1320 | B2105: 14922376 | C2105: INVERSOR CFW500F77P0T4DB20H00 | D2105: FERT | E2105: FA01 | G2105: 033 | H2105: OBSOLETOS DRIVES | K2105: ZWEG | L2105: 0 | M2105: E | O2105: 1 | P2105: 8 | Q2105: 1
A2106: 1320 | B2106: 14922377 | C2106: INVERSOR CFW500F77P0T4DB20C3H00 | D2106: FERT | E2106: FA01 | G2106: 033 | H2106: OBSOLETOS DRIVES | K2106: ZWEG | L2106: 0 | M2106: E | O2106: 1 | P2106: 8 | Q2106: 1
A2107: 1320 | B2107: 14922480 | C2107: INVERSOR CFW500F88P0T4DB20H00 | D2107: FERT | E2107: FA01 | G2107: 033 | H2107: OBSOLETOS DRIVES | K2107: ZWEG | L2107: 0 | M2107: E | O2107: 1 | P2107: 8 | Q2107: 1
A2108: 1320 | B2108: 14922486 | C2108: INVERSOR CFW500F0105T4DB20H00 | D2108: FERT | E2108: FA01 | G2108: 033 | H2108: OBSOLETOS DRIVES | K2108: ZWEG | L2108: 0 | M2108: E | O2108: 1 | P2108: 8 | Q2108: 1
A2109: 1320 | B2109: 14941830 | C2109: INVERSOR EUCFW110107T6OYWZ-UI | D2109: HALB | E2109: FA01 | F2109: FA01 | G2109: 083 | H2109: LINHA G1 | K2109: ZWEG | L2109: 0 | M2109: E | O2109: 1 | P2109: 3 | Q2109: 1
A2110: 1320 | B2110: 14949606 | C2110: INVERSOR CFW700E0180T4NB55C3Y1 | D2110: FERT | E2110: FA01 | F2110: FA01 | G2110: 033 | H2110: OBSOLETOS DRIVES | K2110: ZWEG | L2110: 0 | M2110: E | O2110: 0 | P2110: 1 | Q2110: 0
A2111: 1320 | B2111: 14953012 | C2111: INVERSOR MSCFW110211T4OWH2DCZ-UI | D2111: HALB | E2111: FA01 | F2111: FA01 | G2111: 083 | H2111: LINHA G1 | K2111: ZWEG | L2111: 0 | M2111: E | O2111: 0 | P2111: 3 | Q2111: 0
...
